<?xml version="1.0" ?>
<!-- =================================================================================== -->
<!-- |    This document was autogenerated by xacro from mikrorobot.xacro               | -->
<!-- |    EDITING THIS FILE BY HAND IS NOT RECOMMENDED                                 | -->
<!-- =================================================================================== -->
<!-- Revolute-Revolute Manipulator -->
<robot name="mikrorobot" xmlns:xacro="http://www.ros.org/wiki/xacro">
  <!-- Wheel offset height-direction -->
  <!-- Base Link -->
  <link name="base_link">
    <collision>
      <origin rpy="0 0 0" xyz="0 0 0"/>
      <geometry>
        <box size="0.5 0.3 0.17"/>
      </geometry>
    </collision>
    <visual>
      <origin rpy="0 0 0" xyz="0 0 0"/>
      <geometry>
        <box size="0.5 0.3 0.17"/>
      </geometry>
      <material name="yellow">
        <color rgba="0.8 0.8 0 1"/>
      </material>
    </visual>
    <inertial>
      <origin rpy="0 0 0" xyz="0.25 0.15 0.085"/>
      <mass value="10"/>
      <inertia ixx="0.283333333333" ixy="0.0" ixz="0.0" iyy="0.232416666667" iyz="0.0" izz="0.0990833333333"/>
    </inertial>
  </link>
  <!-- Front Right Wheel -->
  <joint name="joint_f_r_wheel" type="continuous">
    <parent link="base_link"/>
    <child link="f_r_wheel"/>
    <origin rpy="0 0 0" xyz="0.2 -0.2 -0.035"/>
    <axis rpy="0 0 0" xyz="0 1 0"/>
  </joint>
  <link name="f_r_wheel">
    <visual>
      <origin rpy="1.570795 0 0" xyz="0 0 0"/>
      <geometry>
        <cylinder length="0.07" radius="0.1"/>
      </geometry>
      <material name="black">
        <color rgba="0.05 0.05 0.05 1"/>
      </material>
    </visual>
    <collision>
      <origin rpy="1.570795 0 0" xyz="0 0 0"/>
      <geometry>
        <cylinder length="0.07" radius="0.1"/>
      </geometry>
    </collision>
    <inertial>
      <mass value="1.5"/>
      <origin rpy="0 0 0" xyz="0 0 0.035"/>
      <inertia ixx="0.0055875" ixy="0" ixz="0" iyy="0.0055875" iyz="0" izz="0.0075"/>
    </inertial>
  </link>
  <!-- Back Right Wheel -->
  <joint name="joint_b_r_wheel" type="continuous">
    <parent link="base_link"/>
    <child link="b_r_wheel"/>
    <origin rpy="0 0 0" xyz="-0.2 -0.2 -0.035"/>
    <axis rpy="0 0 0" xyz="0 1 0"/>
  </joint>
  <link name="b_r_wheel">
    <visual>
      <origin rpy="1.570795 0 0" xyz="0 0 0"/>
      <geometry>
        <cylinder length="0.07" radius="0.1"/>
      </geometry>
      <material name="black"/>
    </visual>
    <collision>
      <origin rpy="1.570795 0 0" xyz="0 0 0"/>
      <geometry>
        <cylinder length="0.07" radius="0.1"/>
      </geometry>
    </collision>
    <inertial>
      <mass value="1.5"/>
      <origin rpy="0 0 0" xyz="0 0 0.035"/>
      <inertia ixx="0.0055875" ixy="0" ixz="0" iyy="0.0055875" iyz="0" izz="0.0075"/>
    </inertial>
  </link>
  <!-- Front Left Wheel -->
  <joint name="joint_f_l_wheel" type="continuous">
    <parent link="base_link"/>
    <child link="f_l_wheel"/>
    <origin rpy="0 0 0" xyz="0.2 0.2 -0.035"/>
    <axis rpy="0 0 0" xyz="0 1 0"/>
  </joint>
  <link name="f_l_wheel">
    <visual>
      <origin rpy="1.570795 0 0" xyz="0 0 0"/>
      <geometry>
        <cylinder length="0.07" radius="0.1"/>
      </geometry>
      <material name="black"/>
    </visual>
    <collision>
      <origin rpy="1.570795 0 0" xyz="0 0 0"/>
      <geometry>
        <cylinder length="0.07" radius="0.1"/>
      </geometry>
    </collision>
    <inertial>
      <mass value="1.5"/>
      <origin rpy="0 0 0" xyz="0 0 0.035"/>
      <inertia ixx="0.0055875" ixy="0" ixz="0" iyy="0.0055875" iyz="0" izz="0.0075"/>
    </inertial>
  </link>
  <!-- Back Left Wheel -->
  <joint name="joint_b_l_wheel" type="continuous">
    <parent link="base_link"/>
    <child link="b_l_wheel"/>
    <origin rpy="0 0 0" xyz="-0.2 0.2 -0.035"/>
    <axis rpy="0 0 0" xyz="0 1 0"/>
  </joint>
  <link name="b_l_wheel">
    <visual>
      <origin rpy="1.570795 0 0" xyz="0 0 0"/>
      <geometry>
        <cylinder length="0.07" radius="0.1"/>
      </geometry>
      <material name="black"/>
    </visual>
    <collision>
      <origin rpy="1.570795 0 0" xyz="0 0 0"/>
      <geometry>
        <cylinder length="0.07" radius="0.1"/>
      </geometry>
    </collision>
    <inertial>
      <mass value="1.5"/>
      <origin rpy="0 0 0" xyz="0 0 0.035"/>
      <inertia ixx="0.0055875" ixy="0" ixz="0" iyy="0.0055875" iyz="0" izz="0.0075"/>
    </inertial>
  </link>
  <!-- Camera -->
  <link name="camera">
    <collision>
      <origin rpy="0 0 0" xyz="0 0 0"/>
      <geometry>
        <cylinder length="0.03" radius="0.02"/>
      </geometry>
    </collision>
    <visual>
      <origin rpy="0 0 0" xyz="0 0 0"/>
      <geometry>
        <cylinder length="0.03" radius="0.02"/>
      </geometry>
      <material name="black"/>
    </visual>
    <inertial>
      <mass value="1e-5"/>
      <origin rpy="0 0 0" xyz="0 0 0"/>
      <inertia ixx="1e-6" ixy="0" ixz="0" iyy="1e-6" iyz="0" izz="1e-6"/>
    </inertial>
  </link>
  <joint name="camera_joint" type="fixed">
    <parent link="base_link"/>
    <child link="camera"/>
    <origin rpy="-1.570795 0 -1.570795" xyz="0.2 0 0.085"/>
    <axis rpy="0 0 0" xyz="0 1 0"/>
  </joint>
  <transmission name="tran_f_r">
    <type>transmission_interface/SimpleTransmission</type>
    <joint name="joint_f_r_wheel">
      <hardwareInterface>EffortJointInterface</hardwareInterface>
    </joint>
    <actuator name="motor_f_r">
      <hardwareInterface>EffortJointInterface</hardwareInterface>
      <mechanicalReduction>1</mechanicalReduction>
    </actuator>
  </transmission>
  <transmission name="tran_b_r">
    <type>transmission_interface/SimpleTransmission</type>
    <joint name="joint_b_r_wheel">
      <hardwareInterface>EffortJointInterface</hardwareInterface>
    </joint>
    <actuator name="motor_b_r">
      <hardwareInterface>EffortJointInterface</hardwareInterface>
      <mechanicalReduction>1</mechanicalReduction>
    </actuator>
  </transmission>
  <transmission name="tran_f_l">
    <type>transmission_interface/SimpleTransmission</type>
    <joint name="joint_f_l_wheel">
      <hardwareInterface>EffortJointInterface</hardwareInterface>
    </joint>
    <actuator name="motor_f_l">
      <hardwareInterface>EffortJointInterface</hardwareInterface>
      <mechanicalReduction>1</mechanicalReduction>
    </actuator>
  </transmission>
  <transmission name="tran_b_l">
    <type>transmission_interface/SimpleTransmission</type>
    <joint name="joint_b_l_wheel">
      <hardwareInterface>EffortJointInterface</hardwareInterface>
    </joint>
    <actuator name="motor_b_l">
      <hardwareInterface>EffortJointInterface</hardwareInterface>
      <mechanicalReduction>1</mechanicalReduction>
    </actuator>
  </transmission>
</robot>

